Traceback (most recent call last):
  File "/Users/macbook/anaconda3/lib/python3.11/site-packages/jupyter_cache/executors/utils.py", line 58, in single_nb_execution
    executenb(
  File "/Users/macbook/anaconda3/lib/python3.11/site-packages/nbclient/client.py", line 1204, in execute
    return NotebookClient(nb=nb, resources=resources, km=km, **kwargs).execute()
           ^^^^^^^^^^^^^^^^^^^^^^^^^^^^^^^^^^^^^^^^^^^^^^^^^^^^^^^^^^^^^^^^^^^^^
  File "/Users/macbook/anaconda3/lib/python3.11/site-packages/nbclient/util.py", line 84, in wrapped
    return just_run(coro(*args, **kwargs))
           ^^^^^^^^^^^^^^^^^^^^^^^^^^^^^^^
  File "/Users/macbook/anaconda3/lib/python3.11/site-packages/nbclient/util.py", line 62, in just_run
    return loop.run_until_complete(coro)
           ^^^^^^^^^^^^^^^^^^^^^^^^^^^^^
  File "/Users/macbook/anaconda3/lib/python3.11/asyncio/base_events.py", line 653, in run_until_complete
    return future.result()
           ^^^^^^^^^^^^^^^
  File "/Users/macbook/anaconda3/lib/python3.11/site-packages/nbclient/client.py", line 663, in async_execute
    await self.async_execute_cell(
  File "/Users/macbook/anaconda3/lib/python3.11/site-packages/nbclient/client.py", line 965, in async_execute_cell
    await self._check_raise_for_error(cell, cell_index, exec_reply)
  File "/Users/macbook/anaconda3/lib/python3.11/site-packages/nbclient/client.py", line 862, in _check_raise_for_error
    raise CellExecutionError.from_cell_and_msg(cell, exec_reply_content)
nbclient.exceptions.CellExecutionError: An error occurred while executing the following cell:
------------------
import numpy as np
A = np.array([[1, 4], [2, 3]])
eig_result = np.linalg.eig(A)
print("Eigenvalues:", eig_result.eigenvalues)
print("Eigenvectors:", eig_result.eigenvectors[:, 0], eig_result.eigenvectors[:, 1])
------------------

[0;31m---------------------------------------------------------------------------[0m
[0;31mAttributeError[0m                            Traceback (most recent call last)
Cell [0;32mIn[1], line 4[0m
[1;32m      2[0m A [38;5;241m=[39m np[38;5;241m.[39marray([[[38;5;241m1[39m, [38;5;241m4[39m], [[38;5;241m2[39m, [38;5;241m3[39m]])
[1;32m      3[0m eig_result [38;5;241m=[39m np[38;5;241m.[39mlinalg[38;5;241m.[39meig(A)
[0;32m----> 4[0m [38;5;28mprint[39m([38;5;124m"[39m[38;5;124mEigenvalues:[39m[38;5;124m"[39m, eig_result[38;5;241m.[39meigenvalues)
[1;32m      5[0m [38;5;28mprint[39m([38;5;124m"[39m[38;5;124mEigenvectors:[39m[38;5;124m"[39m, eig_result[38;5;241m.[39meigenvectors[:, [38;5;241m0[39m], eig_result[38;5;241m.[39meigenvectors[:, [38;5;241m1[39m])

[0;31mAttributeError[0m: 'tuple' object has no attribute 'eigenvalues'
AttributeError: 'tuple' object has no attribute 'eigenvalues'

